# xml = """
# <mujoco>
#   <worldbody>
#     <light name="top" pos="0 0 1"/>
#     <body name="box_and_sphere" euler="0 0 -30">
#       <joint name="swing" type="hinge" axis="1 -1 0" pos="-.2 -.2 -.2"/>
#       <geom name="red_box" type="box" size=".2 .2 .2" rgba="1 0 0 1"/>
#       <geom name="green_sphere" pos=".2 .2 .2" size=".1" rgba="0 1 0 1"/>
#     </body>
#   </worldbody>
# </mujoco>
# """
# xml = """
# <mujoco>
#   <option gravity="0 0 -9.81"/> <!-- 默认重力 -->
#   <worldbody>
#     <light diffuse=".5 .5 .5" pos="0 0 3" dir="0 0 -1"/>
#     <!-- 地面 -->
#     <geom type="plane" size="1 1 0.1" rgba=".9 0 0 1"/>
#     <body pos="0 0 1">
#       <joint type="free"/>
#       <!-- 为球添加 solref 参数，使其变弹 -->
#       <!-- solref="0.02 1"：第一个值越小越硬，第二个值越接近1越具有弹性 -->
#       <geom type="sphere" size=".1" rgba="0 .9 0 1" solref="0.02 0.9"/>
#     </body>
#   </worldbody>
# </mujoco>
# """